Workbook

Sheet เปรียบเทียบ
A1: เปรียบเทียบกระสอบทราย 3 แบบ (น้ำหนักคิดจากทรายแห้งแบบหลวม)
A3: ทรายหลวมแห้ง ต่ำสุด (กก./ลบ.ม.) | B3: 1400 | C3: ทรายที่เทหรือตักกองไว้หลวมๆ มีช่องอากาศมาก
A4: ทรายหลวมแห้ง สูงสุด (กก./ลบ.ม.) | B4: 1442 | C4: แก้ตัวเลขช่องสีเหลืองได้ น้ำหนักและกราฟคำนวณใหม่เอง
B5: กระสอบมีปีก (GGS) | C5: กระสอบบังเกอร์ทหาร | D5: Flex MSE
A6: ขนาดกระสอบก่อนกรอก ยาว x กว้าง | B6: 1.50 x 0.75 ม. ปีกข้าง 0.35 ม. ส่วนบรรจุ 0.75 x 0.45 ม. | C6: 0.75 x 0.35 ม. | D6: 0.89 x 0.38 ม. (35 x 15 นิ้ว)
A7: ขนาดหลังกรอก | B7: ~0.75 x 0.45 x 0.20 ม. หนา 0.13–0.15 ม. | C7: ~0.75 x 0.31 x 0.13 ม. | D7: 0.76 x 0.30 x 0.14 ม. (30 x 12 x 5.5 นิ้ว)
A8: ทรายต่อใบ | B8: ="~"&TEXT(B16,"0.0")&" ลิตร"&CHAR(10)&"("&B15&" ใบ/คิว)" | C8: =IF(ROUND(C16,0)=ROUND(C17,0),"~"&ROUND(C16,0),"~"&ROUND(C16,0)&"–"&ROUND(C17,0))&" ลิตร" | D8: =IF(D16=D17,"≥ "&ROUND(D16,0),ROUND(D16,0)&"–"&ROUND(D17,0))&" ลิตร"
A9: น้ำหนักต่อใบ | B9: =IF(ROUND(B18,0)=ROUND(B19,0),"~"&ROUND(B18,0),"~"&ROUND(B18,0)&"–"&ROUND(B19,0))&" กก." | C9: =IF(ROUND(C18,0)=ROUND(C19,0),"~"&ROUND(C18,0),"~"&ROUND(C18,0)&"–"&ROUND(C19,0))&" กก." | D9: =IF(ROUND(D18,0)=ROUND(D19,0),"~"&ROUND(D18,0),"~"&ROUND(D18,0)&"–"&ROUND(D19,0))&" กก."
A10: ยกต่อใบ | B10: =B23&" คน" | C10: =C23&" คน" | D10: =D23&" คน"
A11: หมายเหตุ: น้ำหนักคิดจากทรายหลวมแห้ง 1,400–1,442 กก./ลบ.ม. (ช่อง B3 และ B4)
A13: ข้อมูลคำนวณ
B14: กระสอบมีปีก (GGS) | C14: กระสอบบังเกอร์ทหาร | D14: Flex MSE
A15: จำนวนกระสอบต่อทราย 1 คิว (ใบ) | B15: 18 | C15: - | D15: -
A16: ทรายต่อใบ ต่ำสุด (ลิตร) | B16: =1000/B15 | C16: 11 | D16: 32
A17: ทรายต่อใบ สูงสุด (ลิตร) | B17: =B16 | C17: 16.5 | D17: =D16
A18: น้ำหนักต่อใบ ต่ำสุด (กก.) | B18: =B16*$B$3/1000 | C18: =C16*$B$3/1000 | D18: =D16*$B$3/1000
A19: น้ำหนักต่อใบ สูงสุด (กก.) | B19: =B17*$B$4/1000 | C19: =C17*$B$4/1000 | D19: =D17*$B$4/1000
A20: น้ำหนักต่อใบ ค่ากลาง (กก.) | B20: =AVERAGE(B18:B19) | C20: =AVERAGE(C18:C19) | D20: =AVERAGE(D18:D19)
A21: ช่วงบวก (สูงสุด - กลาง) | B21: =B19-B20 | C21: =C19-C20 | D21: =D19-D20
A22: ช่วงลบ (กลาง - ต่ำสุด) | B22: =B20-B18 | C22: =C20-C18 | D22: =D20-D18
A23: ยกต่อใบ (คน) | B23: 2 | C23: 1 | D23: 2
A25: เทียบกับกระสอบมีปีก
B26: กระสอบมีปีก (GGS) | C26: กระสอบบังเกอร์ทหาร | D26: Flex MSE
A27: น้ำหนักต่อใบ (เท่าของกระสอบมีปีก) | B27: =B20/$B$20 | C27: =C20/$B$20 | D27: =D20/$B$20
A28: ทรายต่อใบ (% ของกระสอบมีปีก) | B28: =AVERAGE(B16:B17)/AVERAGE($B$16:$B$17) | C28: =AVERAGE(C16:C17)/AVERAGE($B$16:$B$17) | D28: =AVERAGE(D16:D17)/AVERAGE($B$16:$B$17)

Sheet ขนาด (ตัวเลข)
A1: ขนาดของกระสอบแต่ละแบบ (เมตร)
A3: กระสอบ | B3: ก่อนกรอก ยาว | C3: ก่อนกรอก กว้าง | D3: หลังกรอก ยาว | E3: หลังกรอก กว้าง | F3: หลังกรอก หนา | G3: พื้นที่หลังกรอก (ตร.ม.) | H3: ปริมาตรกล่องครอบ (ลิตร)
A4: กระสอบมีปีก (GGS) | B4: 1.5 | C4: 0.75 | D4: 0.75 | E4: 0.45 | F4: 0.2 | G4: =D4*E4 | H4: =D4*E4*F4*1000
A5: กระสอบบังเกอร์ทหาร | B5: 0.75 | C5: 0.35 | D5: 0.75 | E5: 0.31 | F5: 0.13 | G5: =D5*E5 | H5: =D5*E5*F5*1000
A6: Flex MSE | B6: 0.89 | C6: 0.38 | D6: 0.76 | E6: 0.3 | F6: 0.14 | G6: =D6*E6 | H6: =D6*E6*F6*1000
A8: ปริมาตรกล่องครอบ = ยาว x กว้าง x หนา ของถุงหลังกรอก ส่วนทรายต่อใบในแผ่นแรกเป็นค่าประมาณ ไม่ใช่การวัดจริง

Sheet ข้อมูลประกอบข้อเสนอ
A1: ข้อมูลประกอบข้อเสนอพัฒนากระสอบรูปแบบใหม่
A2: กระสอบมีปีกขนาดใหญ่ กรอกยากและหนักตอนขนย้าย เมื่อเทียบกับกระสอบบังเกอร์และ Flex MSE (น้ำหนักคิดจากทรายหลวมแห้ง ค่าจากแผ่น "เปรียบเทียบ")
A4: 1. น้ำหนักที่ต้องยก
B5: กระสอบมีปีก (GGS) | C5: กระสอบบังเกอร์ทหาร | D5: Flex MSE | E5: ที่มา / สถานะ
A6: น้ำหนักต่อใบ ค่ากลาง (กก.) | B6: ='เปรียบเทียบ'!B20 | C6: ='เปรียบเทียบ'!C20 | D6: ='เปรียบเทียบ'!D20 | E6: คำนวณจากแผ่น "เปรียบเทียบ" (ยังไม่ได้ชั่งจริง)
A7: น้ำหนักต่อคนที่ยก (กก.) | B7: =B6/B15 | C7: =C6/C15 | D7: =D6/D15 | E7: หารด้วยจำนวนคนยกต่อใบ (แถวที่ 15)
A8: เทียบ load constant NIOSH 23 กก. (เท่า) | B8: =B6/23 | C8: =C6/23 | D8: =D6/23 | E8: NIOSH ใช้ 23 กก. เป็นค่าสูงสุดในสภาพยกเหมาะสมที่สุด (CCOHS)
A9: เทียบเกณฑ์ ILO 55 กก. ต่อคน (เท่า) | B9: =B6/55 | C9: =C6/55 | D9: =D6/55 | E9: ILO R128 ผู้ชายผู้ใหญ่ยกคนเดียวไม่ควรเกิน 55 กก. (ยังไม่ได้ตรวจกฎหมายไทย)
A10: ผลเทียบเกณฑ์ NIOSH 23 กก. (คนเดียว) | B10: =IF(B6<=23,"ไม่เกิน","เกิน")&" ("&TEXT(B6/23,"0.0")&" เท่า)" | C10: =IF(C6<=23,"ไม่เกิน","เกิน")&" ("&TEXT(C6/23,"0.0")&" เท่า)" | D10: =IF(D6<=23,"ไม่เกิน","เกิน")&" ("&TEXT(D6/23,"0.0")&" เท่า)" | E10: เกินเกณฑ์ หมายถึงต้องยก 2 คนหรือใช้เครื่องช่วย
A12: 2. การกรอกและการยก
B13: กระสอบมีปีก (GGS) | C13: กระสอบบังเกอร์ทหาร | D13: Flex MSE | E13: ที่มา / สถานะ
A14: ขนาดผ้าก่อนกรอก | B14: 1.50 x 0.75 ม. | C14: 0.75 x 0.35 ม. | D14: 0.89 x 0.38 ม. | E14: แบบ 690044 CE / หน้าร้าน / datasheet Flex MSE
A15: จำนวนคนยกต่อใบ | B15: 2 | C15: 1 | D15: 2 | E15: ผู้ใช้แจ้งว่ามีปีกต้อง 2 คน / ผู้ผลิต Flex ระบุ 2 คน / บังเกอร์ประมาณ 1 คน
A16: ช่องทางที่ทรายลงถุง (ม.) | B16: 0.19 | C16: 0.35 | D16: 0.3 | E16: มีปีก: คอแคบของปีกบนตามแบบ / บังเกอร์: ปากถุง / Flex: ช่องแม่แบบ
A17: ช่องทางทราย เทียบความกว้างที่ต้องเติม | B17: =B16/0.75 | C17: =C16/0.31 | D17: =D16/0.3 | E17: ช่องหารด้วยความกว้างส่วนที่ต้องเติม (0.75 / 0.31 / 0.30 ม.) ยิ่งต่ำยิ่งต้องดันทรายออกข้าง
A18: ลักษณะปาก | B18: กรวยผ้าอ่อน กว้างบน แคบล่าง ปล่อยมือแล้วหุบ | C18: ปากกว้าง ตั้งตรงได้ | D18: ปากถุงแขวนในแม่แบบ | E18: แบบกระสอบมีปีก / ภาพหน้างาน / คลิป Flex MSE
A19: ต้องดันหรือขย้ำทรายออกข้างหรือไม่ | B19: ต้อง ซ้ำหลายรอบ | C19: ไม่ต้อง | D19: ไม่ต้อง (กวาดเข้าช่อง) | E19: คำบอกเล่าของผู้ใช้ + รูปทรงตามแบบ (ยังไม่ได้จับเวลา)
A20: ขนาดหลังกรอกสม่ำเสมอหรือไม่ | B20: ไม่แน่นอน ขึ้นกับการดันทราย | C20: สม่ำเสมอ | D20: สม่ำเสมอ (ขั้นต่ำ 32 ลิตร) | E20: คำบอกเล่าของผู้ใช้ / คลิป Flex MSE
A22: 3. ภาระงานต่อไซต์ (ทรายเท่ากับกระสอบมีปีก 1,000 ใบ)
B23: กระสอบมีปีก (GGS) | C23: กระสอบบังเกอร์ทหาร | D23: Flex MSE | E23: ที่มา / สถานะ
A24: ปริมาตรทรายรวม (ลบ.ม.) | B24: =1000*'เปรียบเทียบ'!$B$16/1000 | C24: =1000*'เปรียบเทียบ'!$B$16/1000 | D24: =1000*'เปรียบเทียบ'!$B$16/1000 | E24: 1,000 ใบ x ทรายต่อใบของกระสอบมีปีก (ไฟล์คำนวณทราย)
A25: จำนวนกระสอบที่ต้องกรอก (ใบ) | B25: =B24*1000/AVERAGE('เปรียบเทียบ'!B16:'เปรียบเทียบ'!B17) | C25: =C24*1000/AVERAGE('เปรียบเทียบ'!C16:'เปรียบเทียบ'!C17) | D25: =D24*1000/AVERAGE('เปรียบเทียบ'!D16:'เปรียบเทียบ'!D17) | E25: หารด้วยทรายต่อใบเฉลี่ยของแต่ละแบบ
A26: น้ำหนักทรายรวมที่ต้องขน (ตัน) | B26: =B25*B6/1000 | C26: =C25*C6/1000 | D26: =D25*D6/1000 | E26: ทรายมวลเท่ากัน เพียงแบ่งเป็นจำนวนใบต่างกัน
A27: จำนวนครั้งที่คนยก (ครั้ง) | B27: =B25*B15 | C27: =C25*C15 | D27: =D25*D15 | E27: จำนวนใบ x จำนวนคนต่อใบ
A28: น้ำหนักที่แต่ละคนยกต่อครั้ง (กก.) | B28: =B7 | C28: =C7 | D28: =D7 | E28: เบากว่าต่อครั้งแต่จำนวนครั้งเพิ่มขึ้น ต้องชั่งน้ำหนักข้อดีข้อเสียนี้
A30: 4. การขนด้วยรถเข็น
B31: กระสอบมีปีก (GGS) | C31: กระสอบบังเกอร์ทหาร | D31: Flex MSE | E31: ที่มา / สถานะ
A32: จำนวนใบที่รถเข็นรับได้ต่อเที่ยว (ใบ) | B32: 2 | C32: 7 | D32: 4 | E32: มีปีก 2 ใบ: คนงานแจ้ง / บังเกอร์ 7 และ Flex 4: ใช้ในอนิเมชั่นเทียบ ยังไม่ได้ทดลองจริง
A33: น้ำหนักทรายต่อเที่ยว (กก.) | B33: =B32*B6 | C33: =C32*C6 | D33: =D32*D6 | E33: จำนวนใบ x น้ำหนักต่อใบ (ไม่รวมตัวรถเข็นและถุง)
A34: ความสูงกองบนรถเข็น (ม.) | B34: =B32*0.2 | C34: =ROUNDUP(C32/2,0)*0.13 | D34: =ROUNDUP(D32/2,0)*0.14 | E34: ประมาณจากความหนาหลังกรอก มีปีกซ้อน 2 ชั้น / บังเกอร์และ Flex เรียง 2 ใบต่อชั้น
A36: 5. ข้อเสนอเกณฑ์ออกแบบกระสอบรูปแบบใหม่ (เบื้องต้น)
A37: หัวข้อ | B37: ค่าเสนอ | C37: เหตุผลจากข้อมูลข้างบน | E37: สถานะ
A38: น้ำหนักกรอกเต็มต่อใบ (กก.) | B38: 25 | C38: ให้คนเดียวยกได้ ใกล้เกณฑ์ NIOSH 23 กก. กระสอบมีปีกปัจจุบัน ~79 กก. เกินราว 3.4 เท่า | E38: ข้อเสนอ ต้องยืนยันหน้างาน
A39: ทรายต่อใบที่สอดคล้อง (ลิตร) | B39: =B38/'เปรียบเทียบ'!B4*1000 | C39: น้ำหนักเสนอหารด้วยความหนาแน่นสูงสุด (ช่อง B4 แผ่นแรก) | E39: คำนวณ
A40: ความกว้างปากหรือช่องกรอก (ม.) | B40: 0.35 | C40: เท่ากระสอบบังเกอร์ที่กางค้างได้เอง ปัจจุบันคอของกระสอบมีปีกแคบ 0.19 ม. | E40: ข้อเสนอ ต้องทดลองกรอกจริง
A41: จำนวนคนที่ต้องใช้กรอก | B41: 1–2 คน | C41: ลดจาก 2 คนตลอด เพราะปากไม่ต้องมีคนจับค้างไว้ | E41: ข้อเสนอ
A42: ปีกข้างและปีกบน | B42: คงไว้ตามหน้าที่ยึดชั้นและกันดินหลุด | C42: ปีกให้กระสอบชั้นบนทับชั้นล่าง ตัวถุงเล็กลงได้โดยเรียงชั้นถี่ขึ้น | E42: ต้องตรวจกับวิศวกรผู้ออกแบบ
A44: 6. ข้อมูลหน้างานที่ควรเก็บเพิ่มให้ข้อเสนอหนักแน่น (ตัวเลขข้างบนยังเป็นค่าคำนวณ)
A45: 1. ชั่งกระสอบมีปีกที่กรอกจริง 5–10 ใบ (กก.) เทียบกับ ~79 กก. ที่คำนวณ
A46: 2. จับเวลากรอก 1 ใบ (นาที) และจดจำนวนคนที่ใช้ เทียบกับกระสอบบังเกอร์ถ้ามี
...
